Building DAG of jobs...
Your conda installation is not configured to use strict channel priorities. This is however crucial for having robust and correct environments (for details, see https://conda-forge.org/docs/user/tipsandtricks.html). Please consider to configure strict priorities by executing 'conda config --set channel_priority strict'.
Creating conda environment config/sourmash.yml...
Downloading and installing remote packages.
CreateCondaEnvironmentException:
Could not create conda environment from /geomicro/data2/kiledal/projects/2023_metagenomics_working_group/20230214_files/working_dir/config/sourmash.yml:
Command:
mamba env create --quiet --file "/geomicro/data2/kiledal/projects/2023_metagenomics_working_group/20230214_files/working_dir/.snakemake/conda/996bfd0bb6da8f68c65125c7927d3b60_.yaml" --prefix "/geomicro/data2/kiledal/projects/2023_metagenomics_working_group/20230214_files/working_dir/.snakemake/conda/996bfd0bb6da8f68c65125c7927d3b60_"
Output:
Retrieving notices: ...working... done

# >>>>>>>>>>>>>>>>>>>>>> ERROR REPORT <<<<<<<<<<<<<<<<<<<<<<

    Traceback (most recent call last):
      File "/geomicro/data2/kiledal/miniconda3/lib/python3.9/site-packages/conda/exceptions.py", line 1118, in __call__
        return func(*args, **kwargs)
      File "/geomicro/data2/kiledal/miniconda3/lib/python3.9/site-packages/conda_env/cli/main.py", line 78, in do_call
        exit_code = getattr(module, func_name)(args, parser)
      File "/geomicro/data2/kiledal/miniconda3/lib/python3.9/site-packages/conda/notices/core.py", line 103, in wrapper
        return_value = func(*args, **kwargs)
      File "/geomicro/data2/kiledal/miniconda3/lib/python3.9/site-packages/conda_env/cli/main_create.py", line 154, in execute
        result[installer_type] = installer.install(prefix, pkg_specs, args, env)
      File "/geomicro/data2/kiledal/miniconda3/lib/python3.9/site-packages/mamba/mamba_env.py", line 55, in mamba_install
        index = load_channels(pool, channel_urls, repos, prepend=False)
      File "/geomicro/data2/kiledal/miniconda3/lib/python3.9/site-packages/mamba/utils.py", line 129, in load_channels
        index = get_index(
      File "/geomicro/data2/kiledal/miniconda3/lib/python3.9/site-packages/mamba/utils.py", line 110, in get_index
        is_downloaded = dlist.download(api.MAMBA_DOWNLOAD_FAILFAST)
    RuntimeError: Download error (28) Timeout was reached [https://repo.anaconda.com/pkgs/r/noarch/repodata.json]
    SSL connection timeout

`$ /geomicro/data2/kiledal/miniconda3/bin/mamba create --quiet --file /geomicro/data2/kiledal/projects/2023_metagenomics_working_group/20230214_files/working_dir/.snakemake/conda/996bfd0bb6da8f68c65125c7927d3b60_.yaml --prefix /geomicro/data2/kiledal/projects/2023_metagenomics_working_group/20230214_files/working_dir/.snakemake/conda/996bfd0bb6da8f68c65125c7927d3b60_`

  environment variables:
                 CIO_TEST=<not set>
  CONDA_AUTO_UPDATE_CONDA=false
        CONDA_DEFAULT_ENV=base
                CONDA_EXE=/geomicro/data2/kiledal/miniconda3/bin/conda
             CONDA_PREFIX=/geomicro/data2/kiledal/miniconda3
    CONDA_PROMPT_MODIFIER=(base)
         CONDA_PYTHON_EXE=/geomicro/data2/kiledal/miniconda3/bin/python
               CONDA_ROOT=/geomicro/data2/kiledal/miniconda3
              CONDA_SHLVL=1
           CURL_CA_BUNDLE=<not set>
               LD_PRELOAD=<not set>
               MODULEPATH=/usr/share/lmod/lmod/modulefiles
                     PATH=/geomicro/data2/kiledal/bin:/geomicro/data2/kiledal/miniconda3/bin:/ge
                          omicro/data2/kiledal/miniconda3/condabin:/geomicro/data2/kiledal/.vsco
                          de-server/bin/e2816fe719a4026ffa1ee0189dc89bdfdbafb164/bin/remote-cli:
                          /usr/local/sbin:/usr/local/bin:/usr/sbin:/usr/bin:/sbin:/bin:/usr/game
                          s:/usr/local/games:/snap/bin
               PYTHONPATH=/geomicro/data2/kiledal/scripts/Phylomark:
       REQUESTS_CA_BUNDLE=<not set>
            SSL_CERT_FILE=<not set>

     active environment : base
    active env location : /geomicro/data2/kiledal/miniconda3
            shell level : 1
       user config file : /geomicro/data2/kiledal/.condarc
 populated config files : 
          conda version : 22.11.1
    conda-build version : not installed
         python version : 3.9.10.final.0
       virtual packages : __archspec=1=x86_64
                          __glibc=2.23=0
                          __linux=4.15.0=0
                          __unix=0=0
       base environment : /geomicro/data2/kiledal/miniconda3  (writable)
      conda av data dir : /geomicro/data2/kiledal/miniconda3/etc/conda
  conda av metadata url : None
           channel URLs : https://repo.anaconda.com/pkgs/main/linux-64
                          https://repo.anaconda.com/pkgs/main/noarch
                          https://repo.anaconda.com/pkgs/r/linux-64
                          https://repo.anaconda.com/pkgs/r/noarch
          package cache : /geomicro/data2/kiledal/miniconda3/pkgs
                          /geomicro/data2/kiledal/.conda/pkgs
       envs directories : /geomicro/data2/kiledal/miniconda3/envs
                          /geomicro/data2/kiledal/.conda/envs
               platform : linux-64
             user-agent : conda/22.11.1 requests/2.28.1 CPython/3.9.10 Linux/4.15.0-132-generic ubuntu/16.04.7 glibc/2.23
                UID:GID : 114296284:10555
             netrc file : None
           offline mode : False


An unexpected error has occurred. Conda has prepared the above report.


